<?xml version="1.0" encoding="UTF-8"?>
<!-- Generated by org.testng.reporters.JUnitXMLReporter -->
<testsuite hostname="DESKTOP-0BR2GDR" failures="1" tests="1" name="Default test" time="29.894" errors="0" timestamp="7 May 2019 19:30:37 GMT">
  <testcase classname="com.testRunner.TRunner" name="feature" time="29.571">
    <failure type="cucumber.runtime.CucumberException" message="java.lang.AssertionError: passed expected [https://www.premierleague.com/?state=success] but found [https://users.premierleague.com/?redirect_uri=https://www.premierleague.com/&amp;amp;app=pl-web]">
      <![CDATA[cucumber.runtime.CucumberException: java.lang.AssertionError: passed expected [https://www.premierleague.com/?state=success] but found [https://users.premierleague.com/?redirect_uri=https://www.premierleague.com/&app=pl-web]
	at cucumber.api.testng.TestNGCucumberRunner.runCucumber(TestNGCucumberRunner.java:69)
	at cucumber.api.testng.AbstractTestNGCucumberTests.feature(AbstractTestNGCucumberTests.java:21)
	at java.base/jdk.internal.reflect.NativeMethodAccessorImpl.invoke0(Native Method)
	at java.base/jdk.internal.reflect.NativeMethodAccessorImpl.invoke(NativeMethodAccessorImpl.java:62)
	at java.base/jdk.internal.reflect.DelegatingMethodAccessorImpl.invoke(DelegatingMethodAccessorImpl.java:43)
	at java.base/java.lang.reflect.Method.invoke(Method.java:566)
	at org.testng.internal.MethodInvocationHelper.invokeMethod(MethodInvocationHelper.java:80)
	at org.testng.internal.Invoker.invokeMethod(Invoker.java:714)
	at org.testng.internal.Invoker.invokeTestMethod(Invoker.java:901)
	at org.testng.internal.Invoker.invokeTestMethods(Invoker.java:1231)
	at org.testng.internal.TestMethodWorker.invokeTestMethods(TestMethodWorker.java:127)
	at org.testng.internal.TestMethodWorker.run(TestMethodWorker.java:111)
	at org.testng.TestRunner.privateRun(TestRunner.java:767)
	at org.testng.TestRunner.run(TestRunner.java:617)
	at org.testng.SuiteRunner.runTest(SuiteRunner.java:334)
	at org.testng.SuiteRunner.runSequentially(SuiteRunner.java:329)
	at org.testng.SuiteRunner.privateRun(SuiteRunner.java:291)
	at org.testng.SuiteRunner.run(SuiteRunner.java:240)
	at org.testng.SuiteRunnerWorker.runSuite(SuiteRunnerWorker.java:52)
	at org.testng.SuiteRunnerWorker.run(SuiteRunnerWorker.java:86)
	at org.testng.TestNG.runSuitesSequentially(TestNG.java:1198)
	at org.testng.TestNG.runSuitesLocally(TestNG.java:1123)
	at org.testng.TestNG.run(TestNG.java:1031)
	at org.testng.remote.AbstractRemoteTestNG.run(AbstractRemoteTestNG.java:115)
	at org.testng.remote.RemoteTestNG.initAndRun(RemoteTestNG.java:251)
	at org.testng.remote.RemoteTestNG.main(RemoteTestNG.java:77)
Caused by: java.lang.AssertionError: passed expected [https://www.premierleague.com/?state=success] but found [https://users.premierleague.com/?redirect_uri=https://www.premierleague.com/&app=pl-web]
	at org.testng.Assert.fail(Assert.java:94)
	at org.testng.Assert.failNotEquals(Assert.java:494)
	at org.testng.Assert.assertEquals(Assert.java:123)
	at org.testng.Assert.assertEquals(Assert.java:176)
	at com.stepsDef.StepDef.user_click_submit_button_and_appear_user_account_page_with_validation(StepDef.java:59)
	at âœ½.And user click submit button and appear user account page with validation(C:/Users/palsa/eclipse-workspaceNew/PleagueFinal/src/main/resources/League.feature:10)
]]>
    </failure>
  </testcase> <!-- feature -->
</testsuite> <!-- Default test -->
